[2022-02-17 14:12:37,020] {taskinstance.py:1032} INFO - Dependencies all met for <TaskInstance: demo_etl.Load_Data.Save_to_DB manual__2022-02-17T14:12:29.672479+00:00 [queued]>
[2022-02-17 14:12:37,063] {taskinstance.py:1032} INFO - Dependencies all met for <TaskInstance: demo_etl.Load_Data.Save_to_DB manual__2022-02-17T14:12:29.672479+00:00 [queued]>
[2022-02-17 14:12:37,063] {taskinstance.py:1238} INFO - 
--------------------------------------------------------------------------------
[2022-02-17 14:12:37,063] {taskinstance.py:1239} INFO - Starting attempt 1 of 1
[2022-02-17 14:12:37,063] {taskinstance.py:1240} INFO - 
--------------------------------------------------------------------------------
[2022-02-17 14:12:37,090] {taskinstance.py:1259} INFO - Executing <Task(PythonOperator): Load_Data.Save_to_DB> on 2022-02-17 14:12:29.672479+00:00
[2022-02-17 14:12:37,095] {standard_task_runner.py:52} INFO - Started process 12596 to run task
[2022-02-17 14:12:37,105] {standard_task_runner.py:76} INFO - Running: ['***', 'tasks', 'run', 'demo_etl', 'Load_Data.Save_to_DB', 'manual__2022-02-17T14:12:29.672479+00:00', '--job-id', '41', '--raw', '--subdir', 'DAGS_FOLDER/demo_etl.py', '--cfg-path', '/tmp/tmpk3gh8zkv', '--error-file', '/tmp/tmph0_nh52d']
[2022-02-17 14:12:37,106] {standard_task_runner.py:77} INFO - Job 41: Subtask Load_Data.Save_to_DB
[2022-02-17 14:12:37,177] {logging_mixin.py:109} INFO - Running <TaskInstance: demo_etl.Load_Data.Save_to_DB manual__2022-02-17T14:12:29.672479+00:00 [running]> on host f8b49ae6ae82
[2022-02-17 14:12:37,246] {taskinstance.py:1426} INFO - Exporting the following env vars:
AIRFLOW_CTX_DAG_OWNER=***
AIRFLOW_CTX_DAG_ID=demo_etl
AIRFLOW_CTX_TASK_ID=Load_Data.Save_to_DB
AIRFLOW_CTX_EXECUTION_DATE=2022-02-17T14:12:29.672479+00:00
AIRFLOW_CTX_DAG_RUN_ID=manual__2022-02-17T14:12:29.672479+00:00
[2022-02-17 14:12:37,254] {logging_mixin.py:109} WARNING - /home/***/.local/lib/python3.7/site-packages/***/utils/context.py:152 AirflowContextDeprecationWarning: Accessing 'execution_date' from the template is deprecated and will be removed in a future version. Please use 'data_interval_start' or 'logical_date' instead.
[2022-02-17 14:12:37,255] {logging_mixin.py:109} WARNING - /home/***/.local/lib/python3.7/site-packages/***/utils/context.py:152 AirflowContextDeprecationWarning: Accessing 'next_ds' from the template is deprecated and will be removed in a future version. Please use '{{ data_interval_end | ds }}' instead.
[2022-02-17 14:12:37,256] {logging_mixin.py:109} WARNING - /home/***/.local/lib/python3.7/site-packages/***/utils/context.py:152 AirflowContextDeprecationWarning: Accessing 'next_ds_nodash' from the template is deprecated and will be removed in a future version. Please use '{{ data_interval_end | ds_nodash }}' instead.
[2022-02-17 14:12:37,257] {logging_mixin.py:109} WARNING - /home/***/.local/lib/python3.7/site-packages/***/utils/context.py:152 AirflowContextDeprecationWarning: Accessing 'next_execution_date' from the template is deprecated and will be removed in a future version. Please use 'data_interval_end' instead.
[2022-02-17 14:12:37,259] {logging_mixin.py:109} WARNING - /home/***/.local/lib/python3.7/site-packages/***/utils/context.py:152 AirflowContextDeprecationWarning: Accessing 'prev_ds' from the template is deprecated and will be removed in a future version.
[2022-02-17 14:12:37,260] {logging_mixin.py:109} WARNING - /home/***/.local/lib/python3.7/site-packages/***/utils/context.py:152 AirflowContextDeprecationWarning: Accessing 'prev_ds_nodash' from the template is deprecated and will be removed in a future version.
[2022-02-17 14:12:37,262] {logging_mixin.py:109} WARNING - /home/***/.local/lib/python3.7/site-packages/***/utils/context.py:152 AirflowContextDeprecationWarning: Accessing 'prev_execution_date' from the template is deprecated and will be removed in a future version.
[2022-02-17 14:12:37,263] {logging_mixin.py:109} WARNING - /home/***/.local/lib/python3.7/site-packages/***/utils/context.py:152 AirflowContextDeprecationWarning: Accessing 'prev_execution_date_success' from the template is deprecated and will be removed in a future version. Please use 'prev_data_interval_start_success' instead.
[2022-02-17 14:12:37,266] {logging_mixin.py:109} WARNING - /home/***/.local/lib/python3.7/site-packages/***/utils/context.py:152 AirflowContextDeprecationWarning: Accessing 'tomorrow_ds' from the template is deprecated and will be removed in a future version.
[2022-02-17 14:12:37,269] {logging_mixin.py:109} WARNING - /home/***/.local/lib/python3.7/site-packages/***/utils/context.py:152 AirflowContextDeprecationWarning: Accessing 'tomorrow_ds_nodash' from the template is deprecated and will be removed in a future version.
[2022-02-17 14:12:37,271] {logging_mixin.py:109} WARNING - /home/***/.local/lib/python3.7/site-packages/***/utils/context.py:152 AirflowContextDeprecationWarning: Accessing 'yesterday_ds' from the template is deprecated and will be removed in a future version.
[2022-02-17 14:12:37,272] {logging_mixin.py:109} WARNING - /home/***/.local/lib/python3.7/site-packages/***/utils/context.py:152 AirflowContextDeprecationWarning: Accessing 'yesterday_ds_nodash' from the template is deprecated and will be removed in a future version.
[2022-02-17 14:12:37,355] {taskinstance.py:1700} ERROR - Task failed with exception
Traceback (most recent call last):
  File "/home/airflow/.local/lib/python3.7/site-packages/airflow/models/taskinstance.py", line 1329, in _run_raw_task
    self._execute_task_with_callbacks(context)
  File "/home/airflow/.local/lib/python3.7/site-packages/airflow/models/taskinstance.py", line 1455, in _execute_task_with_callbacks
    result = self._execute_task(context, self.task)
  File "/home/airflow/.local/lib/python3.7/site-packages/airflow/models/taskinstance.py", line 1511, in _execute_task
    result = execute_callable(context=context)
  File "/home/airflow/.local/lib/python3.7/site-packages/airflow/operators/python.py", line 174, in execute
    return_value = self.execute_callable()
  File "/home/airflow/.local/lib/python3.7/site-packages/airflow/operators/python.py", line 185, in execute_callable
    return self.python_callable(*self.op_args, **self.op_kwargs)
  File "/opt/airflow/dags/functions.py", line 56, in savetodb
    with Engine.begin() as conn:
UnboundLocalError: local variable 'Engine' referenced before assignment
[2022-02-17 14:12:37,373] {taskinstance.py:1277} INFO - Marking task as FAILED. dag_id=demo_etl, task_id=Load_Data.Save_to_DB, execution_date=20220217T141229, start_date=20220217T141237, end_date=20220217T141237
[2022-02-17 14:12:37,412] {standard_task_runner.py:92} ERROR - Failed to execute job 41 for task Load_Data.Save_to_DB
Traceback (most recent call last):
  File "/home/airflow/.local/lib/python3.7/site-packages/airflow/task/task_runner/standard_task_runner.py", line 85, in _start_by_fork
    args.func(args, dag=self.dag)
  File "/home/airflow/.local/lib/python3.7/site-packages/airflow/cli/cli_parser.py", line 48, in command
    return func(*args, **kwargs)
  File "/home/airflow/.local/lib/python3.7/site-packages/airflow/utils/cli.py", line 92, in wrapper
    return f(*args, **kwargs)
  File "/home/airflow/.local/lib/python3.7/site-packages/airflow/cli/commands/task_command.py", line 298, in task_run
    _run_task_by_selected_method(args, dag, ti)
  File "/home/airflow/.local/lib/python3.7/site-packages/airflow/cli/commands/task_command.py", line 107, in _run_task_by_selected_method
    _run_raw_task(args, ti)
  File "/home/airflow/.local/lib/python3.7/site-packages/airflow/cli/commands/task_command.py", line 184, in _run_raw_task
    error_file=args.error_file,
  File "/home/airflow/.local/lib/python3.7/site-packages/airflow/utils/session.py", line 70, in wrapper
    return func(*args, session=session, **kwargs)
  File "/home/airflow/.local/lib/python3.7/site-packages/airflow/models/taskinstance.py", line 1329, in _run_raw_task
    self._execute_task_with_callbacks(context)
  File "/home/airflow/.local/lib/python3.7/site-packages/airflow/models/taskinstance.py", line 1455, in _execute_task_with_callbacks
    result = self._execute_task(context, self.task)
  File "/home/airflow/.local/lib/python3.7/site-packages/airflow/models/taskinstance.py", line 1511, in _execute_task
    result = execute_callable(context=context)
  File "/home/airflow/.local/lib/python3.7/site-packages/airflow/operators/python.py", line 174, in execute
    return_value = self.execute_callable()
  File "/home/airflow/.local/lib/python3.7/site-packages/airflow/operators/python.py", line 185, in execute_callable
    return self.python_callable(*self.op_args, **self.op_kwargs)
  File "/opt/airflow/dags/functions.py", line 56, in savetodb
    with Engine.begin() as conn:
UnboundLocalError: local variable 'Engine' referenced before assignment
[2022-02-17 14:12:37,447] {local_task_job.py:154} INFO - Task exited with return code 1
[2022-02-17 14:12:37,505] {local_task_job.py:264} INFO - 0 downstream tasks scheduled from follow-on schedule check
