[2022-02-17 13:54:35,352] {taskinstance.py:1032} INFO - Dependencies all met for <TaskInstance: demo_etl.Transform_Data manual__2022-02-17T13:54:22.541663+00:00 [queued]>
[2022-02-17 13:54:35,364] {taskinstance.py:1032} INFO - Dependencies all met for <TaskInstance: demo_etl.Transform_Data manual__2022-02-17T13:54:22.541663+00:00 [queued]>
[2022-02-17 13:54:35,365] {taskinstance.py:1238} INFO - 
--------------------------------------------------------------------------------
[2022-02-17 13:54:35,365] {taskinstance.py:1239} INFO - Starting attempt 1 of 1
[2022-02-17 13:54:35,365] {taskinstance.py:1240} INFO - 
--------------------------------------------------------------------------------
[2022-02-17 13:54:35,377] {taskinstance.py:1259} INFO - Executing <Task(PythonOperator): Transform_Data> on 2022-02-17 13:54:22.541663+00:00
[2022-02-17 13:54:35,382] {standard_task_runner.py:52} INFO - Started process 5681 to run task
[2022-02-17 13:54:35,388] {standard_task_runner.py:76} INFO - Running: ['***', 'tasks', 'run', 'demo_etl', 'Transform_Data', 'manual__2022-02-17T13:54:22.541663+00:00', '--job-id', '37', '--raw', '--subdir', 'DAGS_FOLDER/demo_etl.py', '--cfg-path', '/tmp/tmpwygmy7hf', '--error-file', '/tmp/tmpmjpyswdx']
[2022-02-17 13:54:35,390] {standard_task_runner.py:77} INFO - Job 37: Subtask Transform_Data
[2022-02-17 13:54:35,458] {logging_mixin.py:109} INFO - Running <TaskInstance: demo_etl.Transform_Data manual__2022-02-17T13:54:22.541663+00:00 [running]> on host f8b49ae6ae82
[2022-02-17 13:54:35,517] {taskinstance.py:1426} INFO - Exporting the following env vars:
AIRFLOW_CTX_DAG_OWNER=***
AIRFLOW_CTX_DAG_ID=demo_etl
AIRFLOW_CTX_TASK_ID=Transform_Data
AIRFLOW_CTX_EXECUTION_DATE=2022-02-17T13:54:22.541663+00:00
AIRFLOW_CTX_DAG_RUN_ID=manual__2022-02-17T13:54:22.541663+00:00
[2022-02-17 13:54:35,525] {logging_mixin.py:109} WARNING - /home/***/.local/lib/python3.7/site-packages/***/utils/context.py:152 AirflowContextDeprecationWarning: Accessing 'execution_date' from the template is deprecated and will be removed in a future version. Please use 'data_interval_start' or 'logical_date' instead.
[2022-02-17 13:54:35,526] {logging_mixin.py:109} WARNING - /home/***/.local/lib/python3.7/site-packages/***/utils/context.py:152 AirflowContextDeprecationWarning: Accessing 'next_ds' from the template is deprecated and will be removed in a future version. Please use '{{ data_interval_end | ds }}' instead.
[2022-02-17 13:54:35,527] {logging_mixin.py:109} WARNING - /home/***/.local/lib/python3.7/site-packages/***/utils/context.py:152 AirflowContextDeprecationWarning: Accessing 'next_ds_nodash' from the template is deprecated and will be removed in a future version. Please use '{{ data_interval_end | ds_nodash }}' instead.
[2022-02-17 13:54:35,528] {logging_mixin.py:109} WARNING - /home/***/.local/lib/python3.7/site-packages/***/utils/context.py:152 AirflowContextDeprecationWarning: Accessing 'next_execution_date' from the template is deprecated and will be removed in a future version. Please use 'data_interval_end' instead.
[2022-02-17 13:54:35,529] {logging_mixin.py:109} WARNING - /home/***/.local/lib/python3.7/site-packages/***/utils/context.py:152 AirflowContextDeprecationWarning: Accessing 'prev_ds' from the template is deprecated and will be removed in a future version.
[2022-02-17 13:54:35,530] {logging_mixin.py:109} WARNING - /home/***/.local/lib/python3.7/site-packages/***/utils/context.py:152 AirflowContextDeprecationWarning: Accessing 'prev_ds_nodash' from the template is deprecated and will be removed in a future version.
[2022-02-17 13:54:35,531] {logging_mixin.py:109} WARNING - /home/***/.local/lib/python3.7/site-packages/***/utils/context.py:152 AirflowContextDeprecationWarning: Accessing 'prev_execution_date' from the template is deprecated and will be removed in a future version.
[2022-02-17 13:54:35,532] {logging_mixin.py:109} WARNING - /home/***/.local/lib/python3.7/site-packages/***/utils/context.py:152 AirflowContextDeprecationWarning: Accessing 'prev_execution_date_success' from the template is deprecated and will be removed in a future version. Please use 'prev_data_interval_start_success' instead.
[2022-02-17 13:54:35,532] {logging_mixin.py:109} WARNING - /home/***/.local/lib/python3.7/site-packages/***/utils/context.py:152 AirflowContextDeprecationWarning: Accessing 'tomorrow_ds' from the template is deprecated and will be removed in a future version.
[2022-02-17 13:54:35,533] {logging_mixin.py:109} WARNING - /home/***/.local/lib/python3.7/site-packages/***/utils/context.py:152 AirflowContextDeprecationWarning: Accessing 'tomorrow_ds_nodash' from the template is deprecated and will be removed in a future version.
[2022-02-17 13:54:35,534] {logging_mixin.py:109} WARNING - /home/***/.local/lib/python3.7/site-packages/***/utils/context.py:152 AirflowContextDeprecationWarning: Accessing 'yesterday_ds' from the template is deprecated and will be removed in a future version.
[2022-02-17 13:54:35,535] {logging_mixin.py:109} WARNING - /home/***/.local/lib/python3.7/site-packages/***/utils/context.py:152 AirflowContextDeprecationWarning: Accessing 'yesterday_ds_nodash' from the template is deprecated and will be removed in a future version.
[2022-02-17 13:54:37,243] {taskinstance.py:1700} ERROR - Task failed with exception
Traceback (most recent call last):
  File "/home/airflow/.local/lib/python3.7/site-packages/airflow/models/taskinstance.py", line 1329, in _run_raw_task
    self._execute_task_with_callbacks(context)
  File "/home/airflow/.local/lib/python3.7/site-packages/airflow/models/taskinstance.py", line 1455, in _execute_task_with_callbacks
    result = self._execute_task(context, self.task)
  File "/home/airflow/.local/lib/python3.7/site-packages/airflow/models/taskinstance.py", line 1511, in _execute_task
    result = execute_callable(context=context)
  File "/home/airflow/.local/lib/python3.7/site-packages/airflow/operators/python.py", line 174, in execute
    return_value = self.execute_callable()
  File "/home/airflow/.local/lib/python3.7/site-packages/airflow/operators/python.py", line 185, in execute_callable
    return self.python_callable(*self.op_args, **self.op_kwargs)
  File "/opt/airflow/dags/functions.py", line 33, in transform
    dfall = dfall.drop(columns=['ehail_fee', 'store_and_fwd_flag'])
  File "/home/airflow/.local/lib/python3.7/site-packages/pandas/util/_decorators.py", line 311, in wrapper
    return func(*args, **kwargs)
  File "/home/airflow/.local/lib/python3.7/site-packages/pandas/core/frame.py", line 4913, in drop
    errors=errors,
  File "/home/airflow/.local/lib/python3.7/site-packages/pandas/core/generic.py", line 4150, in drop
    obj = obj._drop_axis(labels, axis, level=level, errors=errors)
  File "/home/airflow/.local/lib/python3.7/site-packages/pandas/core/generic.py", line 4185, in _drop_axis
    new_axis = axis.drop(labels, errors=errors)
  File "/home/airflow/.local/lib/python3.7/site-packages/pandas/core/indexes/base.py", line 6017, in drop
    raise KeyError(f"{labels[mask]} not found in axis")
KeyError: "['ehail_fee' 'store_and_fwd_flag'] not found in axis"
[2022-02-17 13:54:37,643] {taskinstance.py:1277} INFO - Marking task as FAILED. dag_id=demo_etl, task_id=Transform_Data, execution_date=20220217T135422, start_date=20220217T135435, end_date=20220217T135437
[2022-02-17 13:54:40,454] {local_task_job.py:212} WARNING - State of this instance has been externally set to failed. Terminating instance.
[2022-02-17 13:54:40,457] {process_utils.py:124} INFO - Sending Signals.SIGTERM to group 5681. PIDs of all processes in the group: [5681]
[2022-02-17 13:54:40,457] {process_utils.py:75} INFO - Sending the signal Signals.SIGTERM to group 5681
[2022-02-17 13:54:40,667] {taskinstance.py:1408} ERROR - Received SIGTERM. Terminating subprocesses.
[2022-02-17 13:54:40,667] {logging_mixin.py:109} WARNING - --- Logging error ---
[2022-02-17 13:54:40,669] {logging_mixin.py:109} WARNING - Traceback (most recent call last):
[2022-02-17 13:54:40,669] {logging_mixin.py:109} WARNING -   File "/home/***/.local/lib/python3.7/site-packages/***/task/task_runner/standard_task_runner.py", line 85, in _start_by_fork
    args.func(args, dag=self.dag)
[2022-02-17 13:54:40,669] {logging_mixin.py:109} WARNING -   File "/home/***/.local/lib/python3.7/site-packages/***/cli/cli_parser.py", line 48, in command
    return func(*args, **kwargs)
[2022-02-17 13:54:40,669] {logging_mixin.py:109} WARNING -   File "/home/***/.local/lib/python3.7/site-packages/***/utils/cli.py", line 92, in wrapper
    return f(*args, **kwargs)
[2022-02-17 13:54:40,670] {logging_mixin.py:109} WARNING -   File "/home/***/.local/lib/python3.7/site-packages/***/cli/commands/task_command.py", line 298, in task_run
    _run_task_by_selected_method(args, dag, ti)
[2022-02-17 13:54:40,670] {logging_mixin.py:109} WARNING -   File "/home/***/.local/lib/python3.7/site-packages/***/cli/commands/task_command.py", line 107, in _run_task_by_selected_method
    _run_raw_task(args, ti)
[2022-02-17 13:54:40,670] {logging_mixin.py:109} WARNING -   File "/home/***/.local/lib/python3.7/site-packages/***/cli/commands/task_command.py", line 184, in _run_raw_task
    error_file=args.error_file,
[2022-02-17 13:54:40,670] {logging_mixin.py:109} WARNING -   File "/home/***/.local/lib/python3.7/site-packages/***/utils/session.py", line 70, in wrapper
    return func(*args, session=session, **kwargs)
[2022-02-17 13:54:40,670] {logging_mixin.py:109} WARNING -   File "/home/***/.local/lib/python3.7/site-packages/***/models/taskinstance.py", line 1329, in _run_raw_task
    self._execute_task_with_callbacks(context)
[2022-02-17 13:54:40,670] {logging_mixin.py:109} WARNING -   File "/home/***/.local/lib/python3.7/site-packages/***/models/taskinstance.py", line 1455, in _execute_task_with_callbacks
    result = self._execute_task(context, self.task)
[2022-02-17 13:54:40,671] {logging_mixin.py:109} WARNING -   File "/home/***/.local/lib/python3.7/site-packages/***/models/taskinstance.py", line 1511, in _execute_task
    result = execute_callable(context=context)
[2022-02-17 13:54:40,671] {logging_mixin.py:109} WARNING -   File "/home/***/.local/lib/python3.7/site-packages/***/operators/python.py", line 174, in execute
    return_value = self.execute_callable()
[2022-02-17 13:54:40,671] {logging_mixin.py:109} WARNING -   File "/home/***/.local/lib/python3.7/site-packages/***/operators/python.py", line 185, in execute_callable
    return self.python_callable(*self.op_args, **self.op_kwargs)
[2022-02-17 13:54:40,671] {logging_mixin.py:109} WARNING -   File "/opt/***/dags/functions.py", line 33, in transform
    dfall = dfall.drop(columns=['ehail_fee', 'store_and_fwd_flag'])
[2022-02-17 13:54:40,671] {logging_mixin.py:109} WARNING -   File "/home/***/.local/lib/python3.7/site-packages/pandas/util/_decorators.py", line 311, in wrapper
    return func(*args, **kwargs)
[2022-02-17 13:54:40,671] {logging_mixin.py:109} WARNING -   File "/home/***/.local/lib/python3.7/site-packages/pandas/core/frame.py", line 4913, in drop
    errors=errors,
[2022-02-17 13:54:40,672] {logging_mixin.py:109} WARNING -   File "/home/***/.local/lib/python3.7/site-packages/pandas/core/generic.py", line 4150, in drop
    obj = obj._drop_axis(labels, axis, level=level, errors=errors)
[2022-02-17 13:54:40,672] {logging_mixin.py:109} WARNING -   File "/home/***/.local/lib/python3.7/site-packages/pandas/core/generic.py", line 4185, in _drop_axis
    new_axis = axis.drop(labels, errors=errors)
[2022-02-17 13:54:40,672] {logging_mixin.py:109} WARNING -   File "/home/***/.local/lib/python3.7/site-packages/pandas/core/indexes/base.py", line 6017, in drop
    raise KeyError(f"{labels[mask]} not found in axis")
[2022-02-17 13:54:40,672] {logging_mixin.py:109} WARNING - KeyError: "['ehail_fee' 'store_and_fwd_flag'] not found in axis"
[2022-02-17 13:54:40,672] {logging_mixin.py:109} WARNING - 
During handling of the above exception, another exception occurred:
[2022-02-17 13:54:40,672] {logging_mixin.py:109} WARNING - Traceback (most recent call last):
[2022-02-17 13:54:40,672] {logging_mixin.py:109} WARNING -   File "/usr/local/lib/python3.7/logging/__init__.py", line 1025, in emit
    msg = self.format(record)
[2022-02-17 13:54:40,673] {logging_mixin.py:109} WARNING -   File "/usr/local/lib/python3.7/logging/__init__.py", line 869, in format
    return fmt.format(record)
[2022-02-17 13:54:40,673] {logging_mixin.py:109} WARNING -   File "/usr/local/lib/python3.7/logging/__init__.py", line 616, in format
    record.exc_text = self.formatException(record.exc_info)
[2022-02-17 13:54:40,673] {logging_mixin.py:109} WARNING -   File "/usr/local/lib/python3.7/logging/__init__.py", line 566, in formatException
    traceback.print_exception(ei[0], ei[1], tb, None, sio)
[2022-02-17 13:54:40,673] {logging_mixin.py:109} WARNING -   File "/usr/local/lib/python3.7/traceback.py", line 104, in print_exception
    type(value), value, tb, limit=limit).format(chain=chain):
[2022-02-17 13:54:40,673] {logging_mixin.py:109} WARNING -   File "/usr/local/lib/python3.7/traceback.py", line 508, in __init__
    capture_locals=capture_locals)
[2022-02-17 13:54:40,673] {logging_mixin.py:109} WARNING -   File "/usr/local/lib/python3.7/traceback.py", line 363, in extract
    f.line
[2022-02-17 13:54:40,674] {logging_mixin.py:109} WARNING -   File "/usr/local/lib/python3.7/traceback.py", line 285, in line
    self._line = linecache.getline(self.filename, self.lineno).strip()
[2022-02-17 13:54:40,674] {logging_mixin.py:109} WARNING -   File "/usr/local/lib/python3.7/linecache.py", line 16, in getline
    lines = getlines(filename, module_globals)
[2022-02-17 13:54:40,674] {logging_mixin.py:109} WARNING -   File "/usr/local/lib/python3.7/linecache.py", line 47, in getlines
    return updatecache(filename, module_globals)
[2022-02-17 13:54:40,674] {logging_mixin.py:109} WARNING -   File "/usr/local/lib/python3.7/linecache.py", line 136, in updatecache
    with tokenize.open(fullname) as fp:
[2022-02-17 13:54:40,674] {logging_mixin.py:109} WARNING -   File "/usr/local/lib/python3.7/tokenize.py", line 449, in open
    encoding, lines = detect_encoding(buffer.readline)
[2022-02-17 13:54:40,674] {logging_mixin.py:109} WARNING -   File "/usr/local/lib/python3.7/tokenize.py", line 418, in detect_encoding
    first = read_or_stop()
[2022-02-17 13:54:40,674] {logging_mixin.py:109} WARNING -   File "/usr/local/lib/python3.7/tokenize.py", line 376, in read_or_stop
    return readline()
[2022-02-17 13:54:40,675] {logging_mixin.py:109} WARNING -   File "/home/***/.local/lib/python3.7/site-packages/***/models/taskinstance.py", line 1410, in signal_handler
    raise AirflowException("Task received SIGTERM signal")
[2022-02-17 13:54:40,675] {logging_mixin.py:109} WARNING - ***.exceptions.AirflowException: Task received SIGTERM signal
[2022-02-17 13:54:40,675] {logging_mixin.py:109} WARNING - Call stack:
[2022-02-17 13:54:40,771] {logging_mixin.py:109} WARNING -   File "/home/***/.local/bin/***", line 8, in <module>
    sys.exit(main())
[2022-02-17 13:54:40,771] {logging_mixin.py:109} WARNING -   File "/home/***/.local/lib/python3.7/site-packages/***/__main__.py", line 48, in main
    args.func(args)
[2022-02-17 13:54:40,771] {logging_mixin.py:109} WARNING -   File "/home/***/.local/lib/python3.7/site-packages/***/cli/cli_parser.py", line 48, in command
    return func(*args, **kwargs)
[2022-02-17 13:54:40,772] {logging_mixin.py:109} WARNING -   File "/home/***/.local/lib/python3.7/site-packages/***/utils/cli.py", line 92, in wrapper
    return f(*args, **kwargs)
[2022-02-17 13:54:40,772] {logging_mixin.py:109} WARNING -   File "/home/***/.local/lib/python3.7/site-packages/***/cli/commands/scheduler_command.py", line 75, in scheduler
    _run_scheduler_job(args=args)
[2022-02-17 13:54:40,772] {logging_mixin.py:109} WARNING -   File "/home/***/.local/lib/python3.7/site-packages/***/cli/commands/scheduler_command.py", line 46, in _run_scheduler_job
    job.run()
[2022-02-17 13:54:40,772] {logging_mixin.py:109} WARNING -   File "/home/***/.local/lib/python3.7/site-packages/***/jobs/base_job.py", line 245, in run
    self._execute()
[2022-02-17 13:54:40,772] {logging_mixin.py:109} WARNING -   File "/home/***/.local/lib/python3.7/site-packages/***/jobs/scheduler_job.py", line 620, in _execute
    self.executor.start()
[2022-02-17 13:54:40,772] {logging_mixin.py:109} WARNING -   File "/home/***/.local/lib/python3.7/site-packages/***/executors/local_executor.py", line 356, in start
    self.impl.start()
[2022-02-17 13:54:40,772] {logging_mixin.py:109} WARNING -   File "/home/***/.local/lib/python3.7/site-packages/***/executors/local_executor.py", line 298, in start
    worker.start()
[2022-02-17 13:54:40,772] {logging_mixin.py:109} WARNING -   File "/usr/local/lib/python3.7/multiprocessing/process.py", line 112, in start
    self._popen = self._Popen(self)
[2022-02-17 13:54:40,772] {logging_mixin.py:109} WARNING -   File "/usr/local/lib/python3.7/multiprocessing/context.py", line 223, in _Popen
    return _default_context.get_context().Process._Popen(process_obj)
[2022-02-17 13:54:40,772] {logging_mixin.py:109} WARNING -   File "/usr/local/lib/python3.7/multiprocessing/context.py", line 277, in _Popen
    return Popen(process_obj)
[2022-02-17 13:54:40,773] {logging_mixin.py:109} WARNING -   File "/usr/local/lib/python3.7/multiprocessing/popen_fork.py", line 20, in __init__
    self._launch(process_obj)
[2022-02-17 13:54:40,773] {logging_mixin.py:109} WARNING -   File "/usr/local/lib/python3.7/multiprocessing/popen_fork.py", line 74, in _launch
    code = process_obj._bootstrap()
[2022-02-17 13:54:40,773] {logging_mixin.py:109} WARNING -   File "/usr/local/lib/python3.7/multiprocessing/process.py", line 297, in _bootstrap
    self.run()
[2022-02-17 13:54:40,773] {logging_mixin.py:109} WARNING -   File "/home/***/.local/lib/python3.7/site-packages/***/executors/local_executor.py", line 67, in run
    return super().run()
[2022-02-17 13:54:40,773] {logging_mixin.py:109} WARNING -   File "/usr/local/lib/python3.7/multiprocessing/process.py", line 99, in run
    self._target(*self._args, **self._kwargs)
[2022-02-17 13:54:40,773] {logging_mixin.py:109} WARNING -   File "/home/***/.local/lib/python3.7/site-packages/***/executors/local_executor.py", line 190, in do_work
    self.execute_work(key=key, command=command)
[2022-02-17 13:54:40,773] {logging_mixin.py:109} WARNING -   File "/home/***/.local/lib/python3.7/site-packages/***/executors/local_executor.py", line 84, in execute_work
    state = self._execute_work_in_fork(command)
[2022-02-17 13:54:40,773] {logging_mixin.py:109} WARNING -   File "/home/***/.local/lib/python3.7/site-packages/***/executors/local_executor.py", line 124, in _execute_work_in_fork
    args.func(args)
[2022-02-17 13:54:40,773] {logging_mixin.py:109} WARNING -   File "/home/***/.local/lib/python3.7/site-packages/***/cli/cli_parser.py", line 48, in command
    return func(*args, **kwargs)
[2022-02-17 13:54:40,773] {logging_mixin.py:109} WARNING -   File "/home/***/.local/lib/python3.7/site-packages/***/utils/cli.py", line 92, in wrapper
    return f(*args, **kwargs)
[2022-02-17 13:54:40,774] {logging_mixin.py:109} WARNING -   File "/home/***/.local/lib/python3.7/site-packages/***/cli/commands/task_command.py", line 298, in task_run
    _run_task_by_selected_method(args, dag, ti)
[2022-02-17 13:54:40,774] {logging_mixin.py:109} WARNING -   File "/home/***/.local/lib/python3.7/site-packages/***/cli/commands/task_command.py", line 105, in _run_task_by_selected_method
    _run_task_by_local_task_job(args, ti)
[2022-02-17 13:54:40,774] {logging_mixin.py:109} WARNING -   File "/home/***/.local/lib/python3.7/site-packages/***/cli/commands/task_command.py", line 163, in _run_task_by_local_task_job
    run_job.run()
[2022-02-17 13:54:40,774] {logging_mixin.py:109} WARNING -   File "/home/***/.local/lib/python3.7/site-packages/***/jobs/base_job.py", line 245, in run
    self._execute()
[2022-02-17 13:54:40,774] {logging_mixin.py:109} WARNING -   File "/home/***/.local/lib/python3.7/site-packages/***/jobs/local_task_job.py", line 103, in _execute
    self.task_runner.start()
[2022-02-17 13:54:40,774] {logging_mixin.py:109} WARNING -   File "/home/***/.local/lib/python3.7/site-packages/***/task/task_runner/standard_task_runner.py", line 41, in start
    self.process = self._start_by_fork()
[2022-02-17 13:54:40,774] {logging_mixin.py:109} WARNING -   File "/home/***/.local/lib/python3.7/site-packages/***/task/task_runner/standard_task_runner.py", line 92, in _start_by_fork
    self._task_instance.task_id,
[2022-02-17 13:54:40,774] {logging_mixin.py:109} WARNING -   File "/usr/local/lib/python3.7/logging/__init__.py", line 1413, in exception
    self.error(msg, *args, exc_info=exc_info, **kwargs)
[2022-02-17 13:54:40,774] {logging_mixin.py:109} WARNING -   File "/usr/local/lib/python3.7/logging/__init__.py", line 1407, in error
    self._log(ERROR, msg, args, **kwargs)
[2022-02-17 13:54:40,774] {logging_mixin.py:109} WARNING -   File "/usr/local/lib/python3.7/logging/__init__.py", line 1514, in _log
    self.handle(record)
[2022-02-17 13:54:40,774] {logging_mixin.py:109} WARNING -   File "/usr/local/lib/python3.7/logging/__init__.py", line 1524, in handle
    self.callHandlers(record)
[2022-02-17 13:54:40,775] {logging_mixin.py:109} WARNING -   File "/usr/local/lib/python3.7/logging/__init__.py", line 1586, in callHandlers
    hdlr.handle(record)
[2022-02-17 13:54:40,775] {logging_mixin.py:109} WARNING -   File "/usr/local/lib/python3.7/logging/__init__.py", line 894, in handle
    self.emit(record)
[2022-02-17 13:54:40,775] {logging_mixin.py:109} WARNING -   File "/home/***/.local/lib/python3.7/site-packages/***/utils/log/file_task_handler.py", line 67, in emit
    self.handler.emit(record)
[2022-02-17 13:54:40,775] {logging_mixin.py:109} WARNING - Message: 'Failed to execute job %s for task %s'
Arguments: (37, 'Transform_Data')
[2022-02-17 13:54:40,814] {process_utils.py:70} INFO - Process psutil.Process(pid=5681, status='terminated', exitcode=1, started='13:54:34') (5681) terminated with exit code 1
